<?xml version="1.0" encoding="utf-8"?>
<!-- This URDF was automatically created by SolidWorks to URDF Exporter! Originally created by Stephen Brawner (brawner@gmail.com) 
     Commit Version: 1.6.0-4-g7f85cfe  Build Version: 1.6.7995.38578
     For more information, please see http://wiki.ros.org/sw_urdf_exporter -->
<robot
  name="infantry_description">
  <link
    name="base_link">
    <inertial>
      <origin
        xyz="0.000173024874217081 0.000258930504932274 -0.0050000000000001"
        rpy="0 0 0" />
      <mass
        value="0.0196349540849362" />
      <inertia
        ixx="3.23158619314575E-06"
        ixy="4.2351647362715E-22"
        ixz="4.95120013580339E-25"
        iyy="3.23158619314575E-06"
        iyz="-2.59747643424031E-23"
        izz="6.13592315154256E-06" />
    </inertial>
    <visual>
      <origin
        xyz="0 0 0"
        rpy="0 0 0" />
      <geometry>
        <mesh
          filename="package://infantry_description/meshes/base_link.STL" />
      </geometry>
      <material
        name="">
        <color
          rgba="1 1 1 1" />
      </material>
    </visual>
    <collision>
      <origin
        xyz="0 0 0"
        rpy="0 0 0" />
      <geometry>
        <mesh
          filename="package://infantry_description/meshes/base_link.STL" />
      </geometry>
    </collision>
  </link>
  <link
    name="yaw_link">
    <inertial>
      <origin
        xyz="-0.00172210557148572 0.0108085866068817 0.0899542602252959"
        rpy="0 0 0" />
      <mass
        value="0.855608991793916" />
      <inertia
        ixx="0.00133927971552095"
        ixy="-9.84192545029226E-07"
        ixz="-8.77835854238758E-06"
        iyy="0.00109313889037699"
        iyz="3.74510792532366E-07"
        izz="0.00144065438236482" />
    </inertial>
    <visual>
      <origin
        xyz="0 0 0"
        rpy="0 0 0" />
      <geometry>
        <mesh
          filename="package://infantry_description/meshes/yaw_link.STL" />
      </geometry>
      <material
        name="">
        <color
          rgba="0.752941176470588 0.752941176470588 0.752941176470588 1" />
      </material>
    </visual>
    <collision>
      <origin
        xyz="0 0 0"
        rpy="0 0 0" />
      <geometry>
        <mesh
          filename="package://infantry_description/meshes/yaw_link.STL" />
      </geometry>
    </collision>
  </link>
  <joint
    name="yaw_joint"
    type="continuous">
    <origin
      xyz="0 0 0"
      rpy="0 0 0" />
    <parent
      link="base_link" />
    <child
      link="yaw_link" />
    <axis
      xyz="0 0 1" />
  </joint>
  <link
    name="pitch_link">
    <inertial>
      <origin
        xyz="0.0125972786957216 -0.00171573226333506 0.0173688401049751"
        rpy="0 0 0" />
      <mass
        value="1.99951875338323" />
      <inertia
        ixx="0.00120986238919901"
        ixy="-2.19790457213519E-06"
        ixz="3.63392530069574E-05"
        iyy="0.00171944132814883"
        iyz="-4.15999763778092E-06"
        izz="0.00248517649548466" />
    </inertial>
    <visual>
      <origin
        xyz="0 0 0"
        rpy="0 0 0" />
      <geometry>
        <mesh
          filename="package://infantry_description/meshes/pitch_link.STL" />
      </geometry>
      <material
        name="">
        <color
          rgba="0.752941176470588 0.752941176470588 0.752941176470588 1" />
      </material>
    </visual>
    <collision>
      <origin
        xyz="0 0 0"
        rpy="0 0 0" />
      <geometry>
        <mesh
          filename="package://infantry_description/meshes/pitch_link.STL" />
      </geometry>
    </collision>
  </link>
  <joint
    name="pitch_joint"
    type="revolute">
    <origin
      xyz="0.00017302 5.8931E-05 0.22842"
      rpy="0 0 0" />
    <parent
      link="yaw_link" />
    <child
      link="pitch_link" />
    <axis
      xyz="0 1 0" />
    <limit
      lower="-0.5"
      upper="0.5"
      effort="0"
      velocity="0" />
  </joint>
  <link
    name="camera_link">
    <inertial>
      <origin
        xyz="-0.0385708844371488 1.92836682675387E-05 -0.00189049651727297"
        rpy="0 0 0" />
      <mass
        value="0.0899033244570677" />
      <inertia
        ixx="1.69655468991881E-05"
        ixy="3.16543535424915E-08"
        ixz="-2.30548045352218E-06"
        iyy="6.54882247890451E-05"
        iyz="-7.27139706319313E-09"
        izz="7.19171948344602E-05" />
    </inertial>
    <visual>
      <origin
        xyz="0 0 0"
        rpy="0 0 0" />
      <geometry>
        <mesh
          filename="package://infantry_description/meshes/camera_link.STL" />
      </geometry>
      <material
        name="">
        <color
          rgba="0.792156862745098 0.819607843137255 0.933333333333333 1" />
      </material>
    </visual>
    <collision>
      <origin
        xyz="0 0 0"
        rpy="0 0 0" />
      <geometry>
        <mesh
          filename="package://infantry_description/meshes/camera_link.STL" />
      </geometry>
    </collision>
  </link>
  <joint
    name="camera_joint"
    type="fixed">
    <origin
      xyz="0.1273 0 -0.0404"
      rpy="0 0 0" />
    <parent
      link="pitch_link" />
    <child
      link="camera_link" />
    <axis
      xyz="0 0 0" />
  </joint>
  <link
    name="camera_optical_link">
    <inertial>
      <origin
        xyz="-1.73472347597681E-17 2.31586277932294E-11 0.00100000000000011"
        rpy="0 0 0" />
      <mass
        value="2.51327412287184E-05" />
      <inertia
        ixx="3.35103216382912E-11"
        ixy="-1.61558713389263E-27"
        ixz="-3.87740912134232E-26"
        iyy="3.35103216382912E-11"
        iyz="3.88021307782635E-19"
        izz="5.02654824574367E-11" />
    </inertial>
    <visual>
      <origin
        xyz="0 0 0"
        rpy="0 0 0" />
      <geometry>
        <mesh
          filename="package://infantry_description/meshes/camera_optical_link.STL" />
      </geometry>
      <material
        name="">
        <color
          rgba="1 1 1 1" />
      </material>
    </visual>
    <collision>
      <origin
        xyz="0 0 0"
        rpy="0 0 0" />
      <geometry>
        <mesh
          filename="package://infantry_description/meshes/camera_optical_link.STL" />
      </geometry>
    </collision>
  </link>
  <joint
    name="camera_optical_joint"
    type="fixed">
    <origin
      xyz="0 0 0"
      rpy="-1.5708 0 -1.5708" />
    <parent
      link="camera_link" />
    <child
      link="camera_optical_link" />
    <axis
      xyz="0 0 0" />
  </joint>
  <link
    name="shoot_pitch_link">
    <inertial>
      <origin
        xyz="-0.0250000003417048 -1.35557164625266E-09 -1.69748615164167E-09"
        rpy="0 0 0" />
      <mass
        value="0.0113490034610931" />
      <inertia
        ixx="4.0998275003199E-07"
        ixy="-2.24066684328364E-20"
        ixz="4.77586553146865E-14"
        iyy="2.56936709607706E-06"
        iyz="-5.29395592033938E-23"
        izz="2.56936709607706E-06" />
    </inertial>
    <visual>
      <origin
        xyz="0 0 0"
        rpy="0 0 0" />
      <geometry>
        <mesh
          filename="package://infantry_description/meshes/shoot_pitch_link.STL" />
      </geometry>
      <material
        name="">
        <color
          rgba="1 1 1 1" />
      </material>
    </visual>
    <collision>
      <origin
        xyz="0 0 0"
        rpy="0 0 0" />
      <geometry>
        <mesh
          filename="package://infantry_description/meshes/shoot_pitch_link.STL" />
      </geometry>
    </collision>
  </link>
  <joint
    name="shoot_pitch_joint"
    type="fixed">
    <origin
      xyz="0.1105 0 0.00055"
      rpy="0 0 0" />
    <parent
      link="pitch_link" />
    <child
      link="shoot_pitch_link" />
    <axis
      xyz="0 0 0" />
  </joint>
  <link
    name="shoot_yaw_link">
    <inertial>
      <origin
        xyz="-0.0219342742639877 -1.35557184401114E-09 -0.0119953169861161"
        rpy="0 0 0" />
      <mass
        value="0.0113490034610931" />
      <inertia
        ixx="9.07116484692178E-07"
        ixy="-1.89788319744167E-20"
        ixz="-9.09043923239658E-07"
        iyy="2.56936709607706E-06"
        iyz="-1.04798811892223E-20"
        izz="2.07223336141687E-06" />
    </inertial>
    <visual>
      <origin
        xyz="0 0 0"
        rpy="0 0 0" />
      <geometry>
        <mesh
          filename="package://infantry_description/meshes/shoot_yaw_link.STL" />
      </geometry>
      <material
        name="">
        <color
          rgba="1 1 1 1" />
      </material>
    </visual>
    <collision>
      <origin
        xyz="0 0 0"
        rpy="0 0 0" />
      <geometry>
        <mesh
          filename="package://infantry_description/meshes/shoot_yaw_link.STL" />
      </geometry>
    </collision>
  </link>
  <joint
    name="shoot_yaw_joint"
    type="revolute">
    <origin
      xyz="0.1105 0 0.00055"
      rpy="0 0 0" />
    <parent
      link="pitch_link" />
    <child
      link="shoot_yaw_link" />
    <axis
      xyz="0 -1 0" />
    <limit
      lower="-0.5"
      upper="0.5"
      effort="0"
      velocity="0" />
  </joint>
  <link
    name="gimbal_odom">
    <inertial>
      <origin
        xyz="-4.03271041560238E-10 0.0680999986444338 -1.33365540833097E-14"
        rpy="0 0 0" />
      <mass
        value="9.81747704246808E-05" />
      <inertia
        ixx="3.57928850506648E-10"
        ixy="-7.75481824268463E-26"
        ixz="3.05834432706011E-27"
        iyy="3.06796157577127E-10"
        iyz="-1.08229021079631E-26"
        izz="3.57928850506648E-10" />
    </inertial>
    <visual>
      <origin
        xyz="0 0 0"
        rpy="0 0 0" />
      <geometry>
        <mesh
          filename="package://infantry_description/meshes/gimbal_odom.STL" />
      </geometry>
      <material
        name="">
        <color
          rgba="1 1 1 1" />
      </material>
    </visual>
    <collision>
      <origin
        xyz="0 0 0"
        rpy="0 0 0" />
      <geometry>
        <mesh
          filename="package://infantry_description/meshes/gimbal_odom.STL" />
      </geometry>
    </collision>
  </link>
  <joint
    name="gimbal_odom_joint"
    type="fixed">
    <origin
      xyz="0.00017302 5.8931E-05 0.22842"
      rpy="0 0 0" />
    <parent
      link="base_link" />
    <child
      link="gimbal_odom" />
    <axis
      xyz="0 0 0" />
  </joint>
</robot>